Workbook

Sheet Hospital_Finance_Data
A1: Encounter_ID | B1: Patient_ID | C1: Encounter_Date | D1: Department | E1: ICD10_Code | F1: CPT_Code | G1: Insurance_Payer | H1: Charges | I1: Allowed_Amount | J1: Paid_Amount | K1: Patient_Responsibility | L1: AR_Balance | M1: Claim_Status | N1: Days_in_AR
A2: 100001 | B2: 40644 | C2: 2025-01-29 | D2: Orthopedics | E2: K21.9 | F2: 99213 | G2: Medicare | H2: 15957 | I2: 14641.29 | J2: 14641.29 | K2: 1315.71 | L2: 1315.71 | M2: Paid | N2: 122
A3: 100002 | B3: 89878 | C3: 2025-03-03 | D3: Oncology | E3: J18.9 | F3: 36415 | G3: Self-Pay | H3: 14736 | I3: 10242.6 | J3: 10242.6 | K3: 4493.4 | L3: 4493.4 | M3: Paid | N3: 62
A4: 100003 | B4: 70490 | C4: 2024-05-08 | D4: Orthopedics | E4: M54.5 | F4: 85025 | G4: Cigna | H4: 8055 | I4: 5287.06 | J4: 5287.06 | K4: 2767.94 | L4: 2767.94 | M4: Paid | N4: 115
A5: 100004 | B5: 44314 | C5: 2024-10-06 | D5: Emergency | E5: E11.9 | F5: 70450 | G5: Medicare | H5: 18823 | I5: 16569.94 | J5: 16569.94 | K5: 2253.06 | L5: 2253.06 | M5: Paid | N5: 84
A6: 100005 | B6: 71007 | C6: 2024-02-01 | D6: Cardiology | E6: K21.9 | F6: 99214 | G6: Self-Pay | H6: 5823 | I6: 3651.72 | J6: 3651.72 | K6: 2171.28 | L6: 2171.28 | M6: Paid | N6: 6
A7: 100006 | B7: 32982 | C7: 2025-01-21 | D7: Cardiology | E7: N39.0 | F7: 85025 | G7: UnitedHealthcare | H7: 16100 | I7: 11924.47 | J7: 8688.69 | K7: 4175.53 | L7: 7411.31 | M7: Partial | N7: 28
A8: 100007 | B8: 80947 | C8: 2025-03-12 | D8: Oncology | E8: R07.9 | F8: 36415 | G8: Cigna | H8: 16754 | I8: 15568.24 | J8: 11046.58 | K8: 1185.76 | L8: 5707.42 | M8: Partial | N8: 111
A9: 100008 | B9: 45480 | C9: 2024-12-20 | D9: Oncology | E9: I10 | F9: 80053 | G9: Aetna | H9: 24179 | I9: 22396.5 | J9: 22396.5 | K9: 1782.5 | L9: 1782.5 | M9: Paid | N9: 114
A10: 100009 | B10: 21441 | C10: 2024-09-12 | D10: Cardiology | E10: R07.9 | F10: 80053 | G10: Medicaid | H10: 7314 | I10: 6344.74 | J10: 6344.74 | K10: 969.26 | L10: 969.26 | M10: Paid | N10: 15
A11: 100010 | B11: 22090 | C11: 2024-12-27 | D11: Pediatrics | E11: M54.5 | F11: 85025 | G11: Self-Pay | H11: 4316 | I11: 3555.91 | J11: 346.92 | K11: 760.09 | L11: 3969.08 | M11: Pending | N11: 61
A12: 100011 | B12: 83129 | C12: 2024-10-28 | D12: Neurology | E12: E11.9 | F12: 36415 | G12: Self-Pay | H12: 15407 | I12: 9208.53 | J12: 9208.53 | K12: 6198.47 | L12: 6198.47 | M12: Paid | N12: 172
A13: 100012 | B13: 94314 | C13: 2024-01-25 | D13: Cardiology | E13: J18.9 | F13: 93000 | G13: Medicare | H13: 20541 | I13: 16529.58 | J13: 10805.04 | K13: 4011.42 | L13: 9735.96 | M13: Partial | N13: 31
... A1501: 101500 | B1501: 21088 | C1501: 2025-04-25 | D1501: Orthopedics | E1501: I10 | F1501: 93000 | G1501: Medicaid | H1501: 24764 | I1501: 17726.67 | J1501: 4716.6 | K1501: 7037.33 | L1501: 20047.4 | M1501: Pending | N1501: 130

Sheet Analysis Dashboard
A1: Hospital Finance Data Analysis Dashboard
A3: 📊 Dataset Overview
A4: Total Encounters: | B4: =COUNTA(Hospital_Finance_Data!A2:A1501) -> 1500
A5: Date Range: | B5: 2024-01-02 to 2025-12-31
A6: Total Charges: | B6: =SUM(Hospital_Finance_Data!H2:H1501) -> 19268577
A7: Total Paid Amount: | B7: =SUM(Hospital_Finance_Data!J2:J1501) -> 10820244
A8: Total AR Balance: | B8: =SUM(Hospital_Finance_Data!L2:L1501) -> 8448333
A9: Collection Rate: | B9: =B7/B6 -> 0.56154868
A11: 📋 Department Analysis | G11: 📈 Claim Status Analysis
A12: Department | B12: Encounters | C12: Total Charges | D12: Total Paid | E12: Avg Days in AR | G12: Claim Status | H12: Count | I12: Total Charges | J12: % of Total
A13: Cardiology | B13: =COUNTIF(Hospital_Finance_Data!D:D,"Cardiology") -> 230 | C13: =SUMIF(Hospital_Finance_Data!D:D,"Cardiology",Hospital_Finance_Data!H:H) -> 2979631 | D13: =SUMIF(Hospital_Finance_Data!D:D,"Cardiology",Hospital_Finance_Data!J:J) -> 1638945.8 | E13: =AVERAGEIF(Hospital_Finance_Data!D:D,"Cardiology",Hospital_Finance_Data!N:N) -> 93.395652 | G13: Paid | H13: =COUNTIF(Hospital_Finance_Data!M:M,"Paid") -> 911 | I13: =SUMIF(Hospital_Finance_Data!M:M,"Paid",Hospital_Finance_Data!H:H) -> 11640314 | J13: =I13/$B$6 -> 0.60410865
A14: Emergency | B14: =COUNTIF(Hospital_Finance_Data!D:D,"Emergency") -> 240 | C14: =SUMIF(Hospital_Finance_Data!D:D,"Emergency",Hospital_Finance_Data!H:H) -> 3123139 | D14: =SUMIF(Hospital_Finance_Data!D:D,"Emergency",Hospital_Finance_Data!J:J) -> 1770907.7 | E14: =AVERAGEIF(Hospital_Finance_Data!D:D,"Emergency",Hospital_Finance_Data!N:N) -> 90.5125 | G14: Partial | H14: =COUNTIF(Hospital_Finance_Data!M:M,"Partial") -> 310 | I14: =SUMIF(Hospital_Finance_Data!M:M,"Partial",Hospital_Finance_Data!H:H) -> 3934290 | J14: =I14/$B$6 -> 0.20418166
A15: Neurology | B15: =COUNTIF(Hospital_Finance_Data!D:D,"Neurology") -> 193 | C15: =SUMIF(Hospital_Finance_Data!D:D,"Neurology",Hospital_Finance_Data!H:H) -> 2645101 | D15: =SUMIF(Hospital_Finance_Data!D:D,"Neurology",Hospital_Finance_Data!J:J) -> 1509986.1 | E15: =AVERAGEIF(Hospital_Finance_Data!D:D,"Neurology",Hospital_Finance_Data!N:N) -> 90.398964 | G15: Pending | H15: =COUNTIF(Hospital_Finance_Data!M:M,"Pending") -> 128 | I15: =SUMIF(Hospital_Finance_Data!M:M,"Pending",Hospital_Finance_Data!H:H) -> 1726271 | J15: =I15/$B$6 -> 0.089589958
A16: Oncology | B16: =COUNTIF(Hospital_Finance_Data!D:D,"Oncology") -> 194 | C16: =SUMIF(Hospital_Finance_Data!D:D,"Oncology",Hospital_Finance_Data!H:H) -> 2602497 | D16: =SUMIF(Hospital_Finance_Data!D:D,"Oncology",Hospital_Finance_Data!J:J) -> 1479532.4 | E16: =AVERAGEIF(Hospital_Finance_Data!D:D,"Oncology",Hospital_Finance_Data!N:N) -> 86.572165 | G16: Denied | H16: =COUNTIF(Hospital_Finance_Data!M:M,"Denied") -> 151 | I16: =SUMIF(Hospital_Finance_Data!M:M,"Denied",Hospital_Finance_Data!H:H) -> 1967702 | J16: =I16/$B$6 -> 0.10211974
A17: Orthopedics | B17: =COUNTIF(Hospital_Finance_Data!D:D,"Orthopedics") -> 219 | C17: =SUMIF(Hospital_Finance_Data!D:D,"Orthopedics",Hospital_Finance_Data!H:H) -> 2807805 | D17: =SUMIF(Hospital_Finance_Data!D:D,"Orthopedics",Hospital_Finance_Data!J:J) -> 1588930.8 | E17: =AVERAGEIF(Hospital_Finance_Data!D:D,"Orthopedics",Hospital_Finance_Data!N:N) -> 82.748858
A18: Pediatrics | B18: =COUNTIF(Hospital_Finance_Data!D:D,"Pediatrics") -> 211 | C18: =SUMIF(Hospital_Finance_Data!D:D,"Pediatrics",Hospital_Finance_Data!H:H) -> 2488184 | D18: =SUMIF(Hospital_Finance_Data!D:D,"Pediatrics",Hospital_Finance_Data!J:J) -> 1306448.8 | E18: =AVERAGEIF(Hospital_Finance_Data!D:D,"Pediatrics",Hospital_Finance_Data!N:N) -> 91.601896 | G18: 💡 Key Insights
A19: Radiology | B19: =COUNTIF(Hospital_Finance_Data!D:D,"Radiology") -> 213 | C19: =SUMIF(Hospital_Finance_Data!D:D,"Radiology",Hospital_Finance_Data!H:H) -> 2622220 | D19: =SUMIF(Hospital_Finance_Data!D:D,"Radiology",Hospital_Finance_Data!J:J) -> 1525492.5 | E19: =AVERAGEIF(Hospital_Finance_Data!D:D,"Radiology",Hospital_Finance_Data!N:N) -> 90.629108 | G19: • Highest Revenue Department: | H19: =INDEX(A13:A19,MATCH(MAX(C13:C19),C13:C19,0)) -> Emergency
G20: • Lowest Collection Dept: | H20: {=INDEX(A13:A19,MATCH(MIN(D13:D19/C13:C19),D13:D19/C13:C19,0))} -> Pediatrics
A21: 🏥 Insurance Payer Analysis | G21: • Total Denied Claims Value: | H21: =SUMIF(Hospital_Finance_Data!M:M,"Denied",Hospital_Finance_Data!H:H) -> 1967702
A22: Insurance Payer | B22: Encounters | C22: Total Charges | D22: Avg Allowed | E22: Denied Count | F22: Denial Rate | G22: • Avg Patient Responsibility: | H22: =AVERAGE(Hospital_Finance_Data!K2:K1501) -> 3233.1601
A23: Medicare | B23: =COUNTIF(Hospital_Finance_Data!G:G,"Medicare") -> 215 | C23: =SUMIF(Hospital_Finance_Data!G:G,"Medicare",Hospital_Finance_Data!H:H) -> 2738026 | D23: =AVERAGEIF(Hospital_Finance_Data!G:G,"Medicare",Hospital_Finance_Data!I:I) -> 9318.5251 | E23: =COUNTIFS(Hospital_Finance_Data!G:G,"Medicare",Hospital_Finance_Data!M:M,"Denied") -> 21 | F23: =E23/B23 -> 0.097674419 | G23: • Claims >90 Days AR: | H23: =COUNTIF(Hospital_Finance_Data!N:N,">90") -> 739
A24: Medicaid | B24: =COUNTIF(Hospital_Finance_Data!G:G,"Medicaid") -> 212 | C24: =SUMIF(Hospital_Finance_Data!G:G,"Medicaid",Hospital_Finance_Data!H:H) -> 2643392 | D24: =AVERAGEIF(Hospital_Finance_Data!G:G,"Medicaid",Hospital_Finance_Data!I:I) -> 9361.2936 | E24: =COUNTIFS(Hospital_Finance_Data!G:G,"Medicaid",Hospital_Finance_Data!M:M,"Denied") -> 25 | F24: =E24/B24 -> 0.11792453 | G24: • High Value Claims (>$20K): | H24: =COUNTIF(Hospital_Finance_Data!H:H,">20000") -> 327
A25: Cigna | B25: =COUNTIF(Hospital_Finance_Data!G:G,"Cigna") -> 218 | C25: =SUMIF(Hospital_Finance_Data!G:G,"Cigna",Hospital_Finance_Data!H:H) -> 2891546 | D25: =AVERAGEIF(Hospital_Finance_Data!G:G,"Cigna",Hospital_Finance_Data!I:I) -> 9993.1301 | E25: =COUNTIFS(Hospital_Finance_Data!G:G,"Cigna",Hospital_Finance_Data!M:M,"Denied") -> 31 | F25: =E25/B25 -> 0.14220183 | G25: • Pending AR Value: | H25: =SUMIF(Hospital_Finance_Data!M:M,"Pending",Hospital_Finance_Data!L:L) -> 1528139.2
A26: Blue Cross | B26: =COUNTIF(Hospital_Finance_Data!G:G,"Blue Cross") -> 220 | C26: =SUMIF(Hospital_Finance_Data!G:G,"Blue Cross",Hospital_Finance_Data!H:H) -> 2799725 | D26: =AVERAGEIF(Hospital_Finance_Data!G:G,"Blue Cross",Hospital_Finance_Data!I:I) -> 9667.8317 | E26: =COUNTIFS(Hospital_Finance_Data!G:G,"Blue Cross",Hospital_Finance_Data!M:M,"Denied") -> 21 | F26: =E26/B26 -> 0.095454545 | G26: • Write-off Risk (Denied): | H26: =SUMIF(Hospital_Finance_Data!M:M,"Denied",Hospital_Finance_Data!L:L) -> 1967702
A27: Aetna | B27: =COUNTIF(Hospital_Finance_Data!G:G,"Aetna") -> 210 | C27: =SUMIF(Hospital_Finance_Data!G:G,"Aetna",Hospital_Finance_Data!H:H) -> 2610691 | D27: =AVERAGEIF(Hospital_Finance_Data!G:G,"Aetna",Hospital_Finance_Data!I:I) -> 9343.1371 | E27: =COUNTIFS(Hospital_Finance_Data!G:G,"Aetna",Hospital_Finance_Data!M:M,"Denied") -> 20 | F27: =E27/B27 -> 0.095238095
A28: UnitedHealthcare | B28: =COUNTIF(Hospital_Finance_Data!G:G,"UnitedHealthcare") -> 233 | C28: =SUMIF(Hospital_Finance_Data!G:G,"UnitedHealthcare",Hospital_Finance_Data!H:H) -> 3146432 | D28: =AVERAGEIF(Hospital_Finance_Data!G:G,"UnitedHealthcare",Hospital_Finance_Data!I:I) -> 10134.075 | E28: =COUNTIFS(Hospital_Finance_Data!G:G,"UnitedHealthcare",Hospital_Finance_Data!M:M,"Denied") -> 18 | F28: =E28/B28 -> 0.077253219
A29: Self-Pay | B29: =COUNTIF(Hospital_Finance_Data!G:G,"Self-Pay") -> 192 | C29: =SUMIF(Hospital_Finance_Data!G:G,"Self-Pay",Hospital_Finance_Data!H:H) -> 2438765 | D29: =AVERAGEIF(Hospital_Finance_Data!G:G,"Self-Pay",Hospital_Finance_Data!I:I) -> 9385.6048 | E29: =COUNTIFS(Hospital_Finance_Data!G:G,"Self-Pay",Hospital_Finance_Data!M:M,"Denied") -> 15 | F29: =E29/B29 -> 0.078125
A65: ⏱️ AR Aging Analysis
A66: AR Aging Bucket | B66: Count | C66: Total AR Balance
A67: 0-30 Days | B67: =COUNTIFS(Hospital_Finance_Data!N:N,">=0",Hospital_Finance_Data!N:N,"<=30") -> 282 | C67: =SUMIFS(Hospital_Finance_Data!L:L,Hospital_Finance_Data!N:N,">=0",Hospital_Finance_Data!N:N,"<=30") -> 1611313
A68: 31-60 Days | B68: =COUNTIFS(Hospital_Finance_Data!N:N,">30",Hospital_Finance_Data!N:N,"<=60") -> 229 | C68: =SUMIFS(Hospital_Finance_Data!L:L,Hospital_Finance_Data!N:N,">30",Hospital_Finance_Data!N:N,"<=60") -> 1298319.7
A69: 61-90 Days | B69: =COUNTIFS(Hospital_Finance_Data!N:N,">60",Hospital_Finance_Data!N:N,"<=90") -> 250 | C69: =SUMIFS(Hospital_Finance_Data!L:L,Hospital_Finance_Data!N:N,">60",Hospital_Finance_Data!N:N,"<=90") -> 1493897.9
A70: 91-120 Days | B70: =COUNTIFS(Hospital_Finance_Data!N:N,">90",Hospital_Finance_Data!N:N,"<=120") -> 235 | C70: =SUMIFS(Hospital_Finance_Data!L:L,Hospital_Finance_Data!N:N,">90",Hospital_Finance_Data!N:N,"<=120") -> 1252929.3
A71: >120 Days | B71: =COUNTIFS(Hospital_Finance_Data!N:N,">120") -> 504 | C71: =SUMIFS(Hospital_Finance_Data!L:L,Hospital_Finance_Data!N:N,">120") -> 2791873
A78: 📌 Key Findings & Recommendations
A81: 1. Revenue Concentration: Emergency and Orthopedics generate highest charges - focus collection efforts here.
A82: 2. Denial Management: Review high-denial payers (Cigna 14.2%, Medicaid 11.8%) for patterns and appeals.
A83: 3. AR Aging Risk: 739 claims (>$4M) over 90 days - prioritize follow-up on aged accounts.
A84: 4. Patient Collections: Avg $3,233 patient responsibility - opportunity for point-of-service collection.
A85: 5. Payer Strategy: Self-Pay and commercial payers may need different collection approaches.
...
